Workbook

Sheet Arcadia 85
B2: Arcadia 80
B4: Цена | C4: 6000000
B6: ТОЛЬКО ФРАНЦИЯ | H6: ФРАНЦИЯ + ОАЭ
B7: Расход на содержание лодки в год | H7: Расход на содержание лодки в год | L7: расчет сезонной стоимости ПМ через коэффициент Х
B9: Наименование | C9: Стоимость за период | D9: Кол-во в год | E9: Сумма | F9: K | H9: Наименование | I9: Стоимость за период | J9: Кол-во в год | K9: Сумма | L9: X | M9: 9
B10: Парковка | C10: =55000/12 -> 4583.3333 | D10: 12 | E10: =C10*D10 -> 55000 | F10: 1.5 | H10: Парковка Франция | I10: =C10 -> 4583.3333 | J10: 12 | K10: =I10*J10 -> 55000 | L10: =M9/M10 -> 0.75 | M10: 12
B11: Management fee | C11: 3000 | D11: 12 | E11: =C11*D11 -> 36000 | H11: Management fee | I11: =C11 -> 3000 | J11: 6 | K11: =I11*J11 -> 18000 | L11: месяц | M11: год
B12: Итого стоимость парковки с менеджментом | C12: =(E10*F10+E11)/D12 -> 9875 | D12: 12 | E12: =C12*D12 -> 118500 | H12: Итого стоимость парковки с менеджментом (ПМ) | I12: =(K10*F10+K11)/J12 -> 16750 | J12: 6 | K12: =I12*J12 -> 100500 | L12: =M12/J12 -> 14812.5 | M12: =E12*L10 -> 88875
B13: Страховка | C13: =C4*1% -> 60000 | D13: 1 | E13: =C13*D13 -> 60000 | H13: Страховка | I13: =C4*0.01 -> 60000 | J13: 1 | K13: =I13*J13 -> 60000
B14: Регистрация яхты на Мальте | C14: 5000 | D14: 1 | E14: =C14*D14 -> 5000 | H14: Парковка Абу-Даби | I14: =I10 -> 4583.3333 | J14: 1 | K14: =I14*J14 -> 4583.3333
B15: Сервис | C15: ='A 85 Service List'!B8 -> 46022.4 | D15: 1 | E15: =C15*D15 -> 46022.4 | H15: Перегон лодки Ф-ОАЭ | I15: 123000 | J15: 2 | K15: =I15*J15 -> 246000
B16: Топливо | C16: 0 | D16: 1 | E16: =C16*D16 -> 0 | H16: Страховка перегона Ф-ОАЭ | I16: =C4*0.002 -> 12000 | J16: 2 | K16: =I16*J16 -> 24000
B17: Регистрация компании | C17: 4000 | D17: 1 | E17: =C17*D17 -> 4000
H18: Регистрация яхты на Мальте | I18: 5000 | J18: 1 | K18: =I18*J18 -> 5000
B19: Стоимость в месяц | D19: Кол-во мес. | E19: Сумма | H19: Сервис | I19: =C15 -> 46022.4 | J19: 1 | K19: =I19*J19 -> 46022.4
B20: Капитан | C20: 3000 | D20: 12 | E20: =C20*D20 -> 36000 | H20: Топливо | J20: 1
B21: Социальные выплаты | C21: 400 | D21: 12 | E21: =C21*D21 -> 4800 | H21: Регистрация компании | I21: 4000 | J21: 1 | K21: =I21*J21 -> 4000
H22: Налоги ОАЭ (?) | K22: =I22*J22 -> 0
B23: Норма комиссии агента | C23: 0.2 | H23: Расходы на компанию ОАЭ
B24: Норма налога на прибыль Мальта | C24: 0.05
H25: Стоимость в месяц | J25: Кол-во мес.
B26: ИТОГО РАСХОДЫ В ГОД | E26: =SUM(E12:E25) -> 274322.4 | H26: Капитан | I26: 3000 | J26: 12 | K26: =I26*J26 -> 36000
H27: Социальные выплаты | I27: 400 | J27: 12 | K27: =I27*J27 -> 4800
B29: Приход | H29: Норма комиссии агента | I29: 0.2
H30: Норма налога на прибыль Мальта | I30: 0.05
B31: Период | C31: Стоимость в день без НДС | D31: Кол-во дней | E31: Сумма
B32: 01 Мая - 30 Сентября | C32: 9000 | D32: 60 | E32: =C32*D32 -> 540000 | H32: ИТОГО РАСХОДЫ В ГОД | K32: =SUM(K12:K31) -> 530905.73
B33: 01 Октября - 30 Апреля | C33: 7000 | D33: 30 | E33: =C33*D33 -> 210000
H35: Приход
B37: ИТОГО ВАЛ ЗА ГОД | E37: =SUM(E32:E36) -> 750000 | H37: Период | I37: Стоимость в день без НДС | J37: Кол-во дней | K37: Сумма
B38: КОМИССИЯ АГЕНТ | E38: =E37*C23 -> 150000 | H38: 01 Мая - 30 Сентября | I38: 9000 | J38: 60 | K38: =I38*J38 -> 540000
B39: РАСХОД НА СОДЕРЖАНИЕ | E39: =E26 -> 274322.4 | H39: 01 Октября - 30 Апреля | I39: 9000 | J39: 60 | K39: =I39*J39 -> 540000
B40: ИТОГО ДОХОД ДО НАЛОГА НА ПРИБЫЛЬ | E40: =E37-E38-E39 -> 325677.6
B41: ИТОГО ДОХОД ПОСЛЕ УПЛАТЫ НАЛОГА НА ПРИБЫЛЬ | E41: =E40-E40*C24 -> 309393.72
B43: РЕНТАБЕЛЬНОСТЬ | E43: =E41/C4 -> 0.05156562 | H43: ИТОГО ВАЛ ЗА ГОД | K43: =K38+K39 -> 1080000
H44: КОМИССИЯ АГЕНТ | K44: =K38*I29 -> 108000
H45: РАСХОД НА СОДЕРЖАНИЕ | K45: =K32 -> 530905.73
B46: Agent's income, gross | C46: K-Money | D46: Fee | E46: Total | H46: ИТОГО ДОХОД ДО НАЛОГА НА ПРИБЫЛЬ | K46: =K43-K44-K45 -> 441094.27
C47: =E10*F10-E10 -> 27500 | D47: =E11 -> 36000 | E47: =C47+D47 -> 63500 | H47: ИТОГО ДОХОД ПОСЛЕ УПЛАТЫ НАЛОГА НА ПРИБЫЛЬ | K47: =K46-K46*I30 -> 419039.55
H49: РЕНТАБЕЛЬНОСТЬ | K49: =K47/C4 -> 0.069839926
...

Sheet A 85 Service List
A2: Сервис в год
A3: Покраска днища | B3: 23352
A4: Сервис лвигателей | B4: 12000
A5: Сервис генератора | B5: 1500
A6: Прочее | B6: 1500
A7: НДС 20% | B7: =(B6+B5+B4+B3)*20% -> 7670.4
A8: ИТОГО | B8: =SUM(B3:B7) -> 46022.4

Sheet Frauscher Demon
B2: Frauscher Demon
B4: Цена | C4: 1500000
B6: ТОЛЬКО ФРАНЦИЯ | I6: ФРАНЦИЯ + ОАЭ
B7: Расход на содержание лодки в год | I7: Расход на содержание лодки в год
M8: сезонная стоимость через коэффициент Х
B9: Наименование | C9: Стоимость за период | D9: Кол-во в год | E9: Сумма | F9: К | I9: Наименование | J9: Стоимость за период | K9: Кол-во в год | L9: Сумма | M9: Х | N9: 9
B10: Парковка | C10: =18211/12 -> 1517.5833 | D10: 12 | E10: =C10*D10 -> 18211 | F10: 1.5 | I10: Парковка Франция | J10: =C10 -> 1517.5833 | K10: 12 | L10: =J10*K10 -> 18211 | M10: =N9/N10 -> 0.75 | N10: 12
B11: Management fee | C11: 1000 | D11: 12 | E11: =C11*D11 -> 12000 | I11: Management fee | J11: =C11 -> 1000 | K11: 9 | L11: =J11*K11 -> 9000 | M11: месяц | N11: год
B12: Итого стоимость парковки с менеджментом | C12: =(E10*F10+E11)/D12 -> 3276.375 | D12: 12 | E12: =C12*D12 -> 39316.5 | I12: Итого стоимость парковки с менеджментом | J12: =(L10*F10+L11)/K12 -> 4035.1667 | K12: 9 | L12: =J12*K12 -> 36316.5 | M12: =N12/K12 -> 3276.375 | N12: =E12*M10 -> 29487.375
B13: Страховка | C13: =C4*1% -> 15000 | D13: 1 | E13: =C13*D13 -> 15000 | I13: Страховка | J13: =C4*0.01 -> 15000 | K13: 1 | L13: =J13*K13 -> 15000
B14: Регистрация яхты на Мальте | C14: 5000 | D14: 1 | E14: =C14*D14 -> 5000 | I14: Парковка Абу-Даби | J14: =J10 -> 1517.5833 | K14: 1 | L14: =J14*K14 -> 1517.5833
B15: Сервис | C15: ='FD Service List'!B8 -> 19848 | D15: 1 | E15: =C15*D15 -> 19848 | I15: Перегон лодки Ф-ОАЭ | J15: 47000 | K15: 2 | L15: =J15*K15 -> 94000
B16: Топливо | C16: 0 | D16: 1 | E16: =C16*D16 -> 0 | I16: Страховка перегона Ф-ОАЭ | J16: =C4*0.002 -> 3000 | K16: 2 | L16: =J16*K16 -> 6000
B17: Регистрация компании | C17: 4000 | D17: 1 | E17: =C17*D17 -> 4000
I18: Регистрация яхты на Мальте | J18: 5000 | K18: 1 | L18: =J18*K18 -> 5000
B19: Стоимость в месяц | D19: Кол-во мес. | E19: Сумма | I19: Сервис | J19: =C15 -> 19848 | K19: 1 | L19: =J19*K19 -> 19848
B20: Капитан | C20: 0 | D20: 12 | E20: =C20*D20 -> 0 | I20: Топливо | K20: 1 | L20: =J20*K20 -> 0
B21: Социальные выплаты | C21: 0 | D21: 12 | E21: =C21*D21 -> 0 | I21: Регистрация компании | J21: 4000 | K21: 1 | L21: =J21*K21 -> 4000
I22: Налоги ОАЭ (?) | L22: =J22*K22 -> 0
B23: Парковка K Money за 5 лет | C23: =C10*5/2 -> 3793.9583 | I23: Расходы на компанию ОАЭ
B24: Норма комиссии агента | C24: 0.2 | L24: =J24*K24 -> 0
B25: Норма налога на прибыль Мальта | C25: 0.05 | I25: Стоимость в месяц | K25: Кол-во мес.
I26: Капитан | K26: 12 | L26: =J26*K26 -> 0
B27: ИТОГО РАСХОДЫ В ГОД | E27: =SUM(E12:E26) -> 83164.5 | I27: Социальные выплаты | K27: 12 | L27: =J27*K27 -> 0
I29: Парковка K Money за 5 лет | J29: =J10*5/2 -> 3793.9583
B30: Приход | I30: Норма комиссии агента | J30: 0.2
I31: Норма налога на прибыль Мальта | J31: 0.05
B32: Период | C32: Стоимость в день без НДС | D32: Кол-во дней | E32: Сумма
B33: 01 Мая - 30 Сентября | C33: 3250 | D33: 60 | E33: =C33*D33 -> 195000 | I33: ИТОГО РАСХОДЫ В ГОД | L33: =SUM(L12:L32) -> 181682.08
B34: 01 Октября - 30 Апреля | C34: 2750 | D34: 30 | E34: =C34*D34 -> 82500
I36: Приход
B38: ИТОГО ВАЛ ЗА ГОД | E38: =SUM(E33:E37) -> 277500 | I38: Период | J38: Стоимость в день без НДС | K38: Кол-во дней | L38: Сумма
B39: КОМИССИЯ АГЕНТ | E39: =E38*C24 -> 55500 | I39: 01 Мая - 30 Сентября | J39: 3250 | K39: 60 | L39: =J39*K39 -> 195000
B40: РАСХОД НА СОДЕРЖАНИЕ | E40: =E27 -> 83164.5 | I40: 01 Октября - 30 Апреля | J40: 3250 | K40: 60 | L40: =J40*K40 -> 195000
B41: ИТОГО ДОХОД ДО НАЛОГА НА ПРИБЫЛЬ | E41: =E38-E39-E40 -> 138835.5
B42: ИТОГО ДОХОД ПОСЛЕ УПЛАТЫ НАЛОГА НА ПРИБЫЛЬ | E42: =E41-E41*C25 -> 131893.73
B44: РЕНТАБЕЛЬНОСТЬ | E44: =E42/C4 -> 0.08792915 | I44: ИТОГО ВАЛ ЗА ГОД | L44: =L39+L40 -> 390000
I45: КОМИССИЯ АГЕНТ | L45: =L39*J30 -> 39000
I46: РАСХОД НА СОДЕРЖАНИЕ | L46: =L33 -> 181682.08
B47: Agent's income, gross | C47: K-Money | D47: Fee | E47: Total | I47: ИТОГО ДОХОД ДО НАЛОГА НА ПРИБЫЛЬ | L47: =L44-L45-L46 -> 169317.92
...

Sheet FD Service List
A2: Сервис в год
A3: Покраска днища | B3: 7540
A4: Сервис лвигателей | B4: 6000
A5: Сервис генератора | B5: 1500
A6: Прочее | B6: 1500
A7: НДС 20% | B7: =(B6+B5+B4+B3)*20% -> 3308
A8: ИТОГО | B8: =SUM(B3:B7) -> 19848

Sheet SACS 55
B2: SACS 55
B4: Цена | C4: 2630000
B6: ТОЛЬКО ФРАНЦИЯ | H6: ФРАНЦИЯ + ОАЭ
B7: Расход на содержание лодки в год | H7: Расходы на содержание лодки в год
L8: сезонная стоимость через коэффициент Х
B9: Наименование | C9: Стоимость за период | D9: Кол-во в год | E9: Сумма | F9: К | H9: Наименование | I9: Стоимость за период | J9: Кол-во в год | K9: Сумма | L9: Х | M9: 9
B10: Парковка | C10: =30000/12 -> 2500 | D10: 12 | E10: =C10*D10 -> 30000 | F10: 1.5 | H10: Парковка Франция | I10: =C10 -> 2500 | J10: 12 | K10: =I10*J10 -> 30000 | L10: =M9/M10 -> 0.75 | M10: 12
B11: Management fee | C11: 1500 | D11: 12 | E11: =C11*D11 -> 18000 | H11: Management fee | I11: =C11 -> 1500 | J11: 6 | K11: =I11*J11 -> 9000 | L11: месяц | M11: год
B12: Итого стоимость парковки с менеджментом | C12: =(E10*F10+E11)/D12 -> 5250 | D12: 12 | E12: =C12*D12 -> 63000 | H12: Итого стоимость парковки с менеджментом | I12: =(K10*F10+K11)/J12 -> 9000 | J12: 6 | K12: =I12*J12 -> 54000 | L12: =M12/J12 -> 7875 | M12: =E12*L10 -> 47250
B13: Страховка | C13: =C4*1% -> 26300 | D13: 1 | E13: =C13*D13 -> 26300 | H13: Страховка | I13: =C4*0.01 -> 26300 | J13: 1 | K13: =I13*J13 -> 26300
B14: Регистрация яхты на Мальте | C14: 5000 | D14: 1 | E14: =C14*D14 -> 5000 | H14: Парковка Абу-Даби | I14: =I10 -> 2500 | J14: 1 | K14: =I14*J14 -> 2500
B15: Сервис | C15: ='S 55 Service LIst'!B8 -> 25771.2 | D15: 1 | E15: =C15*D15 -> 25771.2 | H15: Перегон лодки Ф-ОАЭ | I15: 59000 | J15: 2 | K15: =I15*J15 -> 118000
B16: Топливо | C16: 0 | D16: 1 | E16: =C16*D16 -> 0 | H16: Страховка перегона Ф-ОАЭ | I16: =C4*0.002 -> 5260 | J16: 2 | K16: =I16*J16 -> 10520
B17: Регистрация компании | C17: 4000 | D17: 1 | E17: =C17*D17 -> 4000
H18: Регистрация яхты на Мальте | I18: 5000 | J18: 1 | K18: =I18*J18 -> 5000
B19: Стоимость в месяц | D19: Кол-во мес. | E19: Сумма | H19: Сервис | I19: =C15 -> 25771.2 | J19: 1 | K19: =I19*J19 -> 25771.2
B20: Капитан | C20: 0 | D20: 12 | E20: =C20*D20 -> 0 | H20: Топливо | J20: 1 | K20: =I20*J20 -> 0
B21: Социальные выплаты | C21: 0 | D21: 12 | E21: =C21*D21 -> 0 | H21: Регистрация компании | I21: 4000 | J21: 1 | K21: =I21*J21 -> 4000
H22: Налоги ОАЭ (?) | K22: =I22*J22 -> 0
B23: Норма комиссии агента | C23: 0.2 | H23: Расходы на компанию ОАЭ
B24: Норма налога на прибыль Мальта | C24: 0.05
H25: Стоимость в месяц | J25: Кол-во мес.
B26: ИТОГО РАСХОДЫ В ГОД | E26: =SUM(E12:E25) -> 124071.2 | H26: Капитан | J26: 12 | K26: =I26*J26 -> 0
H27: Социальные выплаты | J27: 12 | K27: =I27*J27 -> 0
B29: Приход | H29: Норма комиссии агента | I29: 0.2
H30: Норма налога на прибыль Мальта | I30: 0.05
B31: Период | C31: Стоимость в день без НДС | D31: Кол-во дней | E31: Сумма
B32: 01 Мая - 30 Сентября | C32: 3750 | D32: 60 | E32: =C32*D32 -> 225000 | H32: ИТОГО РАСХОДЫ В ГОД | K32: =SUM(K12:K31) -> 246091.2
B33: 01 Октября - 30 Апреля | C33: 3300 | D33: 30 | E33: =C33*D33 -> 99000
H35: Приход
B37: ИТОГО ВАЛ ЗА ГОД | E37: =SUM(E32:E36) -> 324000 | H37: Период | I37: Стоимость в день без НДС | J37: Кол-во дней | K37: Сумма
B38: КОМИССИЯ АГЕНТ | E38: =E37*C23 -> 64800 | H38: 01 Мая - 30 Сентября | I38: 3750 | J38: 60 | K38: =I38*J38 -> 225000
B39: РАСХОД НА СОДЕРЖАНИЕ | E39: =E26 -> 124071.2 | H39: 01 Октября - 30 Апреля | I39: 3750 | J39: 60 | K39: =I39*J39 -> 225000
B40: ИТОГО ДОХОД ДО НАЛОГА НА ПРИБЫЛЬ | E40: =E37-E38-E39 -> 135128.8
B41: ИТОГО ДОХОД ПОСЛЕ УПЛАТЫ НАЛОГА НА ПРИБЫЛЬ | E41: =E40-E40*C24 -> 128372.36
B43: РЕНТАБЕЛЬНОСТЬ | E43: =E41/C4 -> 0.048810783 | H43: ИТОГО ВАЛ ЗА ГОД | K43: =K38+K39 -> 450000
H44: КОМИССИЯ АГЕНТ | K44: =K38*I29 -> 45000
H45: РАСХОД НА СОДЕРЖАНИЕ | K45: =K32 -> 246091.2
B46: Agent's income, gross | C46: K-Money | D46: Fee | E46: Total | H46: ИТОГО ДОХОД ДО НАЛОГА НА ПРИБЫЛЬ | K46: =K43-K44-K45 -> 158908.8
C47: =E10*F10-E10 -> 15000 | D47: =E11 -> 18000 | E47: =C47+D47 -> 33000 | H47: ИТОГО ДОХОД ПОСЛЕ УПЛАТЫ НАЛОГА НА ПРИБЫЛЬ | K47: =K46-K46*I30 -> 150963.36
...

Sheet S 55 Service LIst
A2: Сервис в год
A3: Покраска днища | B3: 12476
A4: Сервис лвигателей | B4: 6000
A5: Сервис генератора | B5: 1500
A6: Прочее | B6: 1500
A7: НДС 20% | B7: =(B6+B5+B4+B3)*20% -> 4295.2
A8: ИТОГО | B8: =SUM(B3:B7) -> 25771.2

Sheet Manda S05
B2: Manda S05 (new)
B4: Цена | C4: 950000
B6: ТОЛЬКО ФРАНЦИЯ | H6: ФРАНЦИЯ + ОАЭ
B7: Расход на содержание лодки в год | H7: Расходы на содержание лодки в год
L8: сезонная стоимость через коэффициент Х
B9: Наименование | C9: Стоимость за период | D9: Кол-во в год | E9: Сумма | F9: K | H9: Наименование | I9: Стоимость за период | J9: Кол-во в год | K9: Сумма | L9: Х | M9: 9
B10: Парковка | C10: =25000/12 -> 2083.3333 | D10: 12 | E10: =C10*D10 -> 25000 | F10: 1.5 | H10: Парковка Франция | I10: =C10 -> 2083.3333 | J10: 12 | K10: =I10*J10 -> 25000 | L10: =M9/M10 -> 0.75 | M10: 12
B11: Management fee | C11: 1500 | D11: 12 | E11: =C11*D11 -> 18000 | H11: Management fee | I11: =C11 -> 1500 | J11: 6 | K11: =I11*J11 -> 9000 | L11: месяц | M11: год
B12: Итого стоимость парковки с менеджментом | C12: =(E10*F10+E11)/12 -> 4625 | D12: 12 | E12: =C12*D12 -> 55500 | H12: Итого стоимость парковки с менеджментом | I12: =(K10*F10+K11)/J12 -> 7750 | J12: 6 | K12: =I12*J12 -> 46500 | L12: =M12/J12 -> 6937.5 | M12: =E12*L10 -> 41625
B13: Страховка | C13: =C4*1% -> 9500 | D13: 1 | E13: =C13*D13 -> 9500 | H13: Страховка | I13: =C4*0.01 -> 9500 | J13: 1 | K13: =I13*J13 -> 9500
B14: Регистрация яхты на Мальте | C14: 5000 | D14: 1 | E14: =C14*D14 -> 5000 | H14: Парковка ОАЭ | I14: =I10 -> 2083.3333 | J14: 1 | K14: =I14*J14 -> 2083.3333
B15: Сервис | C15: ='S05 Service List'!B8 -> 21751.2 | D15: 1 | E15: =C15*D15 -> 21751.2 | H15: Перегон лодки Ф-ОАЭ | I15: 59000 | J15: 2 | K15: =I15*J15 -> 118000
B16: Топливо | C16: 0 | D16: 1 | E16: =C16*D16 -> 0 | H16: Страховка перегона Ф-ОАЭ | I16: =C4*0.002 -> 1900 | J16: 2 | K16: =I16*J16 -> 3800
B17: Регистрация компании | C17: 0 | D17: 1 | E17: =C17*D17 -> 0
H18: Регистрация яхты на Мальте | I18: 5000 | J18: 1 | K18: =I18*J18 -> 5000
B19: Стоимость в месяц | D19: Кол-во мес. | E19: Сумма | H19: Сервис | I19: =C15 -> 21751.2 | J19: 1 | K19: =I19*J19 -> 21751.2
B20: Капитан | C20: 0 | D20: 12 | E20: =C20*D20 -> 0 | H20: Топливо | J20: 1
B21: Социальные выплаты | C21: 0 | D21: 12 | E21: =C21*D21 -> 0 | H21: Регистрация компании | I21: 4000 | J21: 1 | K21: =I21*J21 -> 4000
H22: Налоги ОАЭ (?) | K22: =I22*J22 -> 0
B23: Норма комиссии агента | C23: 0.2 | H23: Расходы на компанию ОАЭ | K23: =I23*J23 -> 0
B24: Норма налога на прибыль Мальта | C24: 0.05 | H24: Стоимость в месяц | J24: Кол-во мес.
H25: Капитан | J25: 12 | K25: =I25*J25 -> 0
B26: ИТОГО РАСХОДЫ В ГОД | E26: =SUM(E12:E25) -> 91751.2 | H26: Социальные выплаты | J26: 12 | K26: =I26*J26 -> 0
H28: Норма комиссии агента | I28: 0.2
B29: Приход | H29: Норма налога на прибыль Мальта | I29: 0.05
B31: Период | C31: Стоимость в день без НДС | D31: Кол-во дней | E31: Сумма | H31: ИТОГО РАСХОДЫ В ГОД | K31: =SUM(K12:K30) -> 210634.53
B32: 01 Мая - 30 Сентября | C32: 4000 | D32: 60 | E32: =C32*D32 -> 240000
B33: 01 Октября - 30 Апреля | C33: 3500 | D33: 30 | E33: =C33*D33 -> 105000
H34: Приход
H36: Период | I36: Стоимость в день без НДС | J36: Кол-во дней | K36: Сумма
B37: ИТОГО ВАЛ ЗА ГОД | E37: =SUM(E32:E36) -> 345000 | H37: 01 Мая - 30 Сентября | I37: 4000 | J37: 60 | K37: =I37*J37 -> 240000
B38: КОМИССИЯ АГЕНТ | E38: =E37*C23 -> 69000 | H38: 01 Октября - 30 Апреля | I38: 4000 | J38: 60 | K38: =I38*J38 -> 240000
B39: РАСХОД НА СОДЕРЖАНИЕ | E39: =E26 -> 91751.2
B40: ИТОГО ДОХОД ДО НАЛОГА НА ПРИБЫЛЬ | E40: =E37-E38-E39 -> 184248.8
B41: ИТОГО ДОХОД ПОСЛЕ УПЛАТЫ НАЛОГА НА ПРИБЫЛЬ | E41: =E40-E40*C24 -> 175036.36
H42: ИТОГО ВАЛ ЗА ГОД | K42: =K37+K38 -> 480000
B43: РЕНТАБЕЛЬНОСТЬ | E43: =E41/C4 -> 0.1842488 | H43: КОМИССИЯ АГЕНТ | K43: =K37*I28 -> 48000
H44: РАСХОД НА СОДЕРЖАНИЕ | K44: =K31 -> 210634.53
H45: ИТОГО ДОХОД ДО НАЛОГА НА ПРИБЫЛЬ | K45: =K42-K43-K44 -> 221365.47
B46: Agent's income, gross | C46: K-Money | D46: Fee | E46: Total | H46: ИТОГО ДОХОД ПОСЛЕ УПЛАТЫ НАЛОГА НА ПРИБЫЛЬ | K46: =K45-K45*I29 -> 210297.19
...

Sheet S05 Service List
A2: Сервис в год
A3: Покраска днища | B3: 9126
A4: Сервис лвигателей | B4: 6000
A5: Сервис генератора | B5: 1500
A6: Прочее | B6: 1500
A7: НДС 20% | B7: =(B6+B5+B4+B3)*20% -> 3625.2
A8: ИТОГО | B8: =SUM(B3:B7) -> 21751.2

Sheet TOTAL
B1: ТОЛЬКО ФРАНЦИЯ
C2: Arcadia 80 | D2: Frauscher Demon | E2: SACS 55 | F2: Mandayachts S05 | G2: ВСЕГО
B3: РАЗМЕР ИНВЕСТИЦИЙ | C3: ='Arcadia 85'!C4 -> 6000000 | D3: ='Frauscher Demon'!C4 -> 1500000 | E3: ='SACS 55'!C4 -> 2630000 | F3: ='Manda S05'!C4 -> 950000 | G3: =SUM(C3:F3) -> 11080000
B4: ИТОГО ВАЛ ЗА ГОД | C4: ='Arcadia 85'!E37 -> 750000 | D4: ='Frauscher Demon'!E38 -> 277500 | E4: ='SACS 55'!E37 -> 324000 | F4: ='Manda S05'!E37 -> 345000 | G4: =SUM(C4:F4) -> 1696500
B5: КОМИССИЯ АГЕНТ | C5: ='Arcadia 85'!E38 -> 150000 | D5: ='Frauscher Demon'!E39 -> 55500 | E5: ='SACS 55'!E38 -> 64800 | F5: ='Manda S05'!E38 -> 69000 | G5: =SUM(C5:F5) -> 339300
B6: РАСХОД НА СОДЕРЖАНИЕ | C6: ='Arcadia 85'!E39 -> 274322.4 | D6: ='Frauscher Demon'!E40 -> 83164.5 | E6: ='SACS 55'!E39 -> 124071.2 | F6: ='Manda S05'!E39 -> 91751.2 | G6: =SUM(C6:F6) -> 573309.3
B7: ИТОГО ДОХОД ДО НАЛОГА НА ПРИБЫЛЬ | C7: ='Arcadia 85'!E40 -> 325677.6 | D7: ='Frauscher Demon'!E41 -> 138835.5 | E7: ='SACS 55'!E40 -> 135128.8 | F7: ='Manda S05'!E40 -> 184248.8 | G7: =SUM(C7:F7) -> 783890.7
B8: ИТОГО ДОХОД ПОСЛЕ УПЛАТЫ НАЛОГА НА ПРИБЫЛЬ | C8: ='Arcadia 85'!E41 -> 309393.72 | D8: ='Frauscher Demon'!E42 -> 131893.73 | E8: ='SACS 55'!E41 -> 128372.36 | F8: ='Manda S05'!E41 -> 175036.36 | G8: =SUM(C8:F8) -> 744696.16
B10: РЕНТАБЕЛЬНОСТЬ | C10: ='Arcadia 85'!E43 -> 0.05156562 | D10: ='Frauscher Demon'!E44 -> 0.08792915 | E10: ='SACS 55'!E43 -> 0.048810783 | F10: ='Manda S05'!E43 -> 0.1842488 | G10: =G8/G3 -> 0.067210845
B12: parking | C12: ='Arcadia 85'!C47 -> 27500 | D12: ='Frauscher Demon'!C48 -> 9105.5 | E12: ='SACS 55'!C47 -> 15000 | F12: ='Manda S05'!C47 -> 12500 | G12: =SUM(C12:F12) -> 64105.5
B13: management | C13: ='Arcadia 85'!D47 -> 36000 | D13: ='Frauscher Demon'!D48 -> 12000 | E13: ='SACS 55'!D47 -> 18000 | F13: ='Manda S05'!D47 -> 18000 | G13: =SUM(C13:F13) -> 84000
B14: Agent's income, parking+management | C14: ='Arcadia 85'!E47 -> 63500 | D14: ='Frauscher Demon'!E48 -> 21105.5 | E14: ='SACS 55'!E47 -> 33000 | F14: ='Manda S05'!E47 -> 30500 | G14: =SUM(C14:F14) -> 148105.5
B15: Agent's income, total | C15: =C14+C5 -> 213500 | D15: =D14+D5 -> 76605.5 | E15: =E14+E5 -> 97800 | F15: =F14+F5 -> 99500 | G15: =G14+G5 -> 487405.5
B18: ФРАНЦИЯ + ОАЭ
C19: Arcadia 80 | D19: Frauscher Demon | E19: SACS 55 | F19: Mandayachts S05 | G19: ВСЕГО
B20: РАЗМЕР ИНВЕСТИЦИЙ | C20: ='Arcadia 85'!C4 -> 6000000 | D20: ='Frauscher Demon'!C4 -> 1500000 | E20: ='SACS 55'!C4 -> 2630000 | F20: ='Manda S05'!C4 -> 950000 | G20: =SUM(C20:F20) -> 11080000
B21: ИТОГО ВАЛ ЗА ГОД | C21: ='Arcadia 85'!K43 -> 1080000 | D21: ='Frauscher Demon'!L44 -> 390000 | E21: ='SACS 55'!K43 -> 450000 | F21: ='Manda S05'!K42 -> 480000 | G21: =SUM(C21:F21) -> 2400000
B22: КОМИССИЯ АГЕНТ | C22: ='Arcadia 85'!K44 -> 108000 | D22: ='Frauscher Demon'!L45 -> 39000 | E22: ='SACS 55'!K44 -> 45000 | F22: ='Manda S05'!K43 -> 48000 | G22: =SUM(C22:F22) -> 240000
B23: РАСХОД НА СОДЕРЖАНИЕ | C23: ='Arcadia 85'!K45 -> 530905.73 | D23: ='Frauscher Demon'!L46 -> 181682.08 | E23: ='SACS 55'!K45 -> 246091.2 | F23: ='Manda S05'!K44 -> 210634.53 | G23: =SUM(C23:F23) -> 1169313.6
B24: ИТОГО ДОХОД ДО НАЛОГА НА ПРИБЫЛЬ | C24: ='Arcadia 85'!K46 -> 441094.27 | D24: ='Frauscher Demon'!L47 -> 169317.92 | E24: ='SACS 55'!K46 -> 158908.8 | F24: ='Manda S05'!K45 -> 221365.47 | G24: =SUM(C24:F24) -> 990686.45
B25: ИТОГО ДОХОД ПОСЛЕ УПЛАТЫ НАЛОГА НА ПРИБЫЛЬ | C25: ='Arcadia 85'!K47 -> 419039.55 | D25: ='Frauscher Demon'!L48 -> 160852.02 | E25: ='SACS 55'!K47 -> 150963.36 | F25: ='Manda S05'!K46 -> 210297.19 | G25: =SUM(C25:F25) -> 941152.13
B27: РЕНТАБЕЛЬНОСТЬ | C27: ='Arcadia 85'!K49 -> 0.069839926 | D27: ='Frauscher Demon'!L50 -> 0.10723468 | E27: ='SACS 55'!K49 -> 0.057400517 | F27: ='Manda S05'!K48 -> 0.22136547 | G27: =G25/G20 -> 0.084941528
B29: K-Money | C29: ='Arcadia 85'!I52 -> 27500 | D29: ='Frauscher Demon'!J53 -> 9105.5 | E29: ='SACS 55'!I52 -> 15000 | F29: ='Manda S05'!I51 -> 12500 | G29: =SUM(C29:F29) -> 64105.5
B30: Fee | C30: ='Arcadia 85'!J52 -> 18000 | D30: ='Frauscher Demon'!K53 -> 9000 | E30: ='SACS 55'!J52 -> 9000 | F30: ='Manda S05'!J51 -> 9000 | G30: =SUM(C30:F30) -> 45000
B31: Agents income, parking+management | C31: ='Arcadia 85'!K52 -> 45500 | D31: ='Frauscher Demon'!L53 -> 18105.5 | E31: ='SACS 55'!K52 -> 24000 | F31: ='Manda S05'!K51 -> 21500 | G31: =SUM(C31:F31) -> 109105.5
B32: Agents income, total | C32: =C31+C22 -> 153500 | D32: =D31+D22 -> 57105.5 | E32: =E31+E22 -> 69000 | F32: =F31+F22 -> 69500 | G32: =G31+G22 -> 349105.5
B36: menegment fee
B38: Arcadia | C38: 3000
B39: Frauscher | C39: 1000
B40: Sacs | C40: 1500
B41: Manda 05 | C41: 1500
B42: Manda 07 | C42: 2500
